<?xml version="1.0" encoding="utf-8"?>
<!-- This URDF was automatically created by SolidWorks to URDF Exporter! Originally created by Stephen Brawner (brawner@gmail.com) 
     Commit Version: 1.6.0-1-g15f4949  Build Version: 1.6.7594.29634
     For more information, please see http://wiki.ros.org/sw_urdf_exporter -->
<robot
  name="RM65B_EG24C2_description">
  <link
    name="base_link">
    <inertial>
      <origin
        xyz="-0.00043263 -3.2791E-05 0.059984"
        rpy="0 0 0" />
      <mass
        value="0.84048" />
      <inertia
        ixx="0.001724"
        ixy="2.4863E-06"
        ixz="-3.6767E-05"
        iyy="0.0017077"
        iyz="1.7187E-06"
        izz="0.00090401" />
    </inertial>
    <visual>
      <origin
        xyz="0 0 0"
        rpy="0 0 0" />
      <geometry>
        <mesh
          filename="package://RM65B_EG24C2_description/DAE/base_link.dae" />
      </geometry>
      <material
        name="">
        <color
          rgba="0.75294 0.75294 0.75294 1" />
      </material>
    </visual>
    <collision>
      <origin
        xyz="0 0 0"
        rpy="0 0 0" />
      <geometry>
        <mesh
          filename="package://RM65B_EG24C2_description/DAE/base_link.dae" />
      </geometry>
    </collision>
  </link>
  <link
    name="Link_1">
    <inertial>
      <origin
        xyz="1.4674E-07 0.021109 -0.025186"
        rpy="0 0 0" />
      <mass
        value="0.59356" />
      <inertia
        ixx="0.0012661"
        ixy="-1.2311E-08"
        ixz="-1.0059E-08"
        iyy="0.0011817"
        iyz="-0.00021122"
        izz="0.00056135" />
    </inertial>
    <visual>
      <origin
        xyz="0 0 0"
        rpy="0 0 0" />
      <geometry>
        <mesh
          filename="package://RM65B_EG24C2_description/DAE/Link_1.dae" />
      </geometry>
      <material
        name="">
        <color
          rgba="0.75294 0.75294 0.75294 1" />
      </material>
    </visual>
    <collision>
      <origin
        xyz="0 0 0"
        rpy="0 0 0" />
      <geometry>
        <mesh
          filename="package://RM65B_EG24C2_description/DAE/Link_1.dae" />
      </geometry>
    </collision>
  </link>
  <joint
    name="joint_1"
    type="revolute">
    <origin
      xyz="0 0 0.2405"
      rpy="0 0 0" />
    <parent
      link="base_link" />
    <child
      link="Link_1" />
    <axis
      xyz="0 0 1" />
    <limit
      lower="-3.106"
      upper="3.106"
      effort="60"
      velocity="3.14" />
  </joint>
  <link
    name="Link_2">
    <inertial>
      <origin
        xyz="0.15226 4.2499E-07 -0.0062026"
        rpy="0 0 0" />
      <mass
        value="0.86418" />
      <inertia
        ixx="0.00063253"
        ixy="-8.8019E-09"
        ixz="0.00042163"
        iyy="0.0020527"
        iyz="2.3805E-09"
        izz="0.0019528" />
    </inertial>
    <visual>
      <origin
        xyz="0 0 0"
        rpy="0 0 0" />
      <geometry>
        <mesh
          filename="package://RM65B_EG24C2_description/DAE/Link_2.dae" />
      </geometry>
      <material
        name="">
        <color
          rgba="0.75294 0.75294 0.75294 1" />
      </material>
    </visual>
    <collision>
      <origin
        xyz="0 0 0"
        rpy="0 0 0" />
      <geometry>
        <mesh
          filename="package://RM65B_EG24C2_description/DAE/Link_2.dae" />
      </geometry>
    </collision>
  </link>
  <joint
    name="joint_2"
    type="revolute">
    <origin
      xyz="0 0 0"
      rpy="1.5708 -1.5708 0" />
    <parent
      link="Link_1" />
    <child
      link="Link_2" />
    <axis
      xyz="0 0 1" />
    <limit
      lower="-2.269"
      upper="2.269"
      effort="60"
      velocity="3.14" />
  </joint>
  <link
    name="Link_3">
    <inertial>
      <origin
        xyz="4.8002E-06 -0.059593 0.010569"
        rpy="0 0 0" />
      <mass
        value="0.28965" />
      <inertia
        ixx="0.00063737"
        ixy="-5.9731E-08"
        ixz="-3.331E-08"
        iyy="0.00015649"
        iyz="-0.00014461"
        izz="0.00061418" />
    </inertial>
    <visual>
      <origin
        xyz="0 0 0"
        rpy="0 0 0" />
      <geometry>
        <mesh
          filename="package://RM65B_EG24C2_description/DAE/Link_3.dae" />
      </geometry>
      <material
        name="">
        <color
          rgba="0.75294 0.75294 0.75294 1" />
      </material>
    </visual>
    <collision>
      <origin
        xyz="0 0 0"
        rpy="0 0 0" />
      <geometry>
        <mesh
          filename="package://RM65B_EG24C2_description/DAE/Link_3.dae" />
      </geometry>
    </collision>
  </link>
  <joint
    name="joint_3"
    type="revolute">
    <origin
      xyz="0.256 0 0"
      rpy="0 0 1.5708" />
    <parent
      link="Link_2" />
    <child
      link="Link_3" />
    <axis
      xyz="0 0 1" />
    <limit
      lower="-2.356"
      upper="2.356"
      effort="30"
      velocity="3.14" />
  </joint>
  <link
    name="Link_4">
    <inertial>
      <origin
        xyz="2.1531E-06 -0.018042 -0.021539"
        rpy="0 0 0" />
      <mass
        value="0.23942" />
      <inertia
        ixx="0.00028594"
        ixy="2.854E-09"
        ixz="-1.9595E-09"
        iyy="0.00026273"
        iyz="4.4237E-05"
        izz="0.00011989" />
    </inertial>
    <visual>
      <origin
        xyz="0 0 0"
        rpy="0 0 0" />
      <geometry>
        <mesh
          filename="package://RM65B_EG24C2_description/DAE/Link_4.dae" />
      </geometry>
      <material
        name="">
        <color
          rgba="0.75294 0.75294 0.75294 1" />
      </material>
    </visual>
    <collision>
      <origin
        xyz="0 0 0"
        rpy="0 0 0" />
      <geometry>
        <mesh
          filename="package://RM65B_EG24C2_description/DAE/Link_4.dae" />
      </geometry>
    </collision>
  </link>
  <joint
    name="joint_4"
    type="revolute">
    <origin
      xyz="0 -0.21 0"
      rpy="1.5708 0 0" />
    <parent
      link="Link_3" />
    <child
      link="Link_4" />
    <axis
      xyz="0 0 1" />
    <limit
      lower="-3.106"
      upper="3.106"
      effort="10"
      velocity="3.14" />
  </joint>
  <link
    name="Link_5">
    <inertial>
      <origin
        xyz="4.5765E-06 -0.059382 0.0073678"
        rpy="0 0 0" />
      <mass
        value="0.21879" />
      <inertia
        ixx="0.00035053"
        ixy="-3.1704E-08"
        ixz="-1.7465E-08"
        iyy="0.00010492"
        iyz="-7.824E-05"
        izz="0.00033447" />
    </inertial>
    <visual>
      <origin
        xyz="0 0 0"
        rpy="0 0 0" />
      <geometry>
        <mesh
          filename="package://RM65B_EG24C2_description/DAE/Link_5.dae" />
      </geometry>
      <material
        name="">
        <color
          rgba="0.75294 0.75294 0.75294 1" />
      </material>
    </visual>
    <collision>
      <origin
        xyz="0 0 0"
        rpy="0 0 0" />
      <geometry>
        <mesh
          filename="package://RM65B_EG24C2_description/DAE/Link_5.dae" />
      </geometry>
    </collision>
  </link>
  <joint
    name="joint_5"
    type="revolute">
    <origin
      xyz="0 0 0"
      rpy="-1.5708 0 0" />
    <parent
      link="Link_4" />
    <child
      link="Link_5" />
    <axis
      xyz="0 0 1" />
    <limit
      lower="-2.234"
      upper="2.234"
      effort="10"
      velocity="3.14" />
  </joint>
  <link
    name="Link_6">
    <inertial>
      <origin
        xyz="0.00081643 1.3298E-05 -0.012705"
        rpy="0 0 0" />
      <mass
        value="0.065035" />
      <inertia
        ixx="2.1143E-05"
        ixy="-2.2878E-08"
        ixz="-2.5601E-08"
        iyy="1.811E-05"
        iyz="-1.0178E-08"
        izz="3.19E-05" />
    </inertial>
    <visual>
      <origin
        xyz="0 0 0"
        rpy="0 0 0" />
      <geometry>
        <mesh
          filename="package://RM65B_EG24C2_description/DAE/Link_6.dae" />
      </geometry>
      <material
        name="">
        <color
          rgba="0.75294 0.75294 0.75294 1" />
      </material>
    </visual>
    <collision>
      <origin
        xyz="0 0 0"
        rpy="0 0 0" />
      <geometry>
        <mesh
          filename="package://RM65B_EG24C2_description/DAE/Link_6.dae" />
      </geometry>
    </collision>
  </link>
  <joint
    name="joint_6"
    type="revolute">
    <origin
      xyz="0 -0.144 0"
      rpy="1.5708 0 0" />
    <parent
      link="Link_5" />
    <child
      link="Link_6" />
    <axis
      xyz="0 0 1" />
    <limit
      lower="-6.28"
      upper="6.28"
      effort="10"
      velocity="3.14" />
  </joint>
  
  
<!--   夹爪部分  -->
  <link
    name="gripper_base_link">
    <inertial>
      <origin
        xyz="-6.7908E-06 -3.0546E-06 0.038387"
        rpy="0 0 0" />
      <mass
        value="0.07993" />
      <inertia
        ixx="6.2249E-05"
        ixy="-5.6831E-09"
        ixz="-4.5401E-09"
        iyy="5.235E-05"
        iyz="-2.0297E-08"
        izz="2.2082E-05" />
    </inertial>
    <visual>
      <origin
        xyz="0 0 0"
        rpy="0 0 0" />
      <geometry>
        <mesh
          filename="package://RM65B_EG24C2_description/DAE/gripper_base_link.dae" />
      </geometry>
      <material
        name="">
        <color
          rgba="0.75294 0.75294 0.75294 1" />
      </material>
    </visual>
    <collision>
      <origin
        xyz="0 0 0"
        rpy="0 0 0" />
      <geometry>
        <mesh
          filename="package://RM65B_EG24C2_description/DAE/gripper_base_link.dae" />
      </geometry>
    </collision>
  </link>
  <joint
    name="gripper_base_joint"
    type="fixed">
    <origin
      xyz="0 0 -0.001"
      rpy="0 0 0" />
    <parent
      link="Link_6" />
    <child
      link="gripper_base_link" />
    <axis
      xyz="0 0 0" />
  </joint>
  <link
    name="Link_7">
    <inertial>
      <origin
        xyz="0.009 -0.0087669 0.013992"
        rpy="0 0 0" />
      <mass
        value="0.0024292" />
      <inertia
        ixx="5.7398E-07"
        ixy="8.6673E-19"
        ixz="-1.3659E-18"
        iyy="5.1061E-07"
        iyz="2.508E-07"
        izz="2.6747E-07" />
    </inertial>
    <visual>
      <origin
        xyz="0 0 0"
        rpy="0 0 0" />
      <geometry>
        <mesh
          filename="package://RM65B_EG24C2_description/DAE/Link_7.dae" />
      </geometry>
      <material
        name="">
        <color
          rgba="0.75294 0.75294 0.75294 1" />
      </material>
    </visual>
    <collision>
      <origin
        xyz="0 0 0"
        rpy="0 0 0" />
      <geometry>
        <mesh
          filename="package://RM65B_EG24C2_description/DAE/Link_7.dae" />
      </geometry>
    </collision>
  </link>
  <joint
    name="gripper_joint"
    type="revolute">
    <origin
      xyz="-0.009 0.04 0.083"
      rpy="0 0 0" />
    <parent
      link="gripper_base_link" />
    <child
      link="Link_7" />
    <axis
      xyz="-1 0 0" />
    <limit
      lower="0"
      upper="0.82"
      effort="1"
      velocity="1" />
  </joint>
  <link
    name="Link_11">
    <inertial>
      <origin
        xyz="0.009 -0.011864 0.011367"
        rpy="0 0 0" />
      <mass
        value="0.0045068" />
      <inertia
        ixx="5.3203E-07"
        ixy="9.5605E-14"
        ixz="-5.8579E-14"
        iyy="5.1288E-07"
        iyz="9.4703E-08"
        izz="2.009E-07" />
    </inertial>
    <visual>
      <origin
        xyz="0 0 0"
        rpy="0 0 0" />
      <geometry>
        <mesh
          filename="package://RM65B_EG24C2_description/DAE/Link_11.dae" />
      </geometry>
      <material
        name="">
        <color
          rgba="0.75294 0.75294 0.75294 1" />
      </material>
    </visual>
    <collision>
      <origin
        xyz="0 0 0"
        rpy="0 0 0" />
      <geometry>
        <mesh
          filename="package://RM65B_EG24C2_description/DAE/Link_11.dae" />
      </geometry>
    </collision>
  </link>
  <joint
    name="joint_11"
    type="revolute">
    <origin
      xyz="0 -0.0223 0.035591"
      rpy="0 0 0" />
    <parent
      link="Link_7" />
    <child
      link="Link_11" />
    <axis
      xyz="1 0 0" />
    <limit
      lower="0"
      upper="0.82"
      effort="1"
      velocity="1" />
    <mimic joint="gripper_joint" multiplier="1"  offset="0"/>
  </joint>
  <link
    name="Link_8">
    <inertial>
      <origin
        xyz="0.009 -0.0087435 0.013955"
        rpy="0 0 0" />
      <mass
        value="0.0038971" />
      <inertia
        ixx="6.2305E-07"
        ixy="1.0706E-18"
        ixz="-1.6842E-18"
        iyy="5.6941E-07"
        iyz="2.6891E-07"
        izz="3.0871E-07" />
    </inertial>
    <visual>
      <origin
        xyz="0 0 0"
        rpy="0 0 0" />
      <geometry>
        <mesh
          filename="package://RM65B_EG24C2_description/DAE/Link_8.dae" />
      </geometry>
      <material
        name="">
        <color
          rgba="0.75294 0.75294 0.75294 1" />
      </material>
    </visual>
    <collision>
      <origin
        xyz="0 0 0"
        rpy="0 0 0" />
      <geometry>
        <mesh
          filename="package://RM65B_EG24C2_description/DAE/Link_8.dae" />
      </geometry>
    </collision>
  </link>
  <joint
    name="joint_8"
    type="revolute">
    <origin
      xyz="-0.009 0.03 0.085"
      rpy="0 0 0" />
    <parent
      link="gripper_base_link" />
    <child
      link="Link_8" />
    <axis
      xyz="-1 0 0" />
    <limit
      lower="0"
      upper="0.82"
      effort="1"
      velocity="1" />
    <mimic joint="gripper_joint" multiplier="1"  offset="0"/>
  </joint>
  <link
    name="Link_9">
    <inertial>
      <origin
        xyz="0.009 0.0087435 0.013955"
        rpy="0 0 0" />
      <mass
        value="0.0038971" />
      <inertia
        ixx="6.2305E-07"
        ixy="-1.0655E-18"
        ixz="-1.8021E-18"
        iyy="5.6941E-07"
        iyz="-2.6891E-07"
        izz="3.0871E-07" />
    </inertial>
    <visual>
      <origin
        xyz="0 0 0"
        rpy="0 0 0" />
      <geometry>
        <mesh
          filename="package://RM65B_EG24C2_description/DAE/Link_9.dae" />
      </geometry>
      <material
        name="">
        <color
          rgba="0.75294 0.75294 0.75294 1" />
      </material>
    </visual>
    <collision>
      <origin
        xyz="0 0 0"
        rpy="0 0 0" />
      <geometry>
        <mesh
          filename="package://RM65B_EG24C2_description/DAE/Link_9.dae" />
      </geometry>
    </collision>
  </link>
  <joint
    name="joint_9"
    type="revolute">
    <origin
      xyz="-0.009 -0.03 0.085"
      rpy="0 0 0" />
    <parent
      link="gripper_base_link" />
    <child
      link="Link_9" />
    <axis
      xyz="-1 0 0" />
    <limit
      lower="-0.82"
      upper="0"
      effort="1"
      velocity="1" />
    <mimic joint="gripper_joint" multiplier="-1"  offset="0"/>
  </joint>
  <link
    name="Link_10">
    <inertial>
      <origin
        xyz="0.009 0.0087669 0.013992"
        rpy="0 0 0" />
      <mass
        value="0.0024292" />
      <inertia
        ixx="5.7398E-07"
        ixy="9.5542E-19"
        ixz="7.7727E-19"
        iyy="5.1061E-07"
        iyz="-2.508E-07"
        izz="2.6747E-07" />
    </inertial>
    <visual>
      <origin
        xyz="0 0 0"
        rpy="0 0 0" />
      <geometry>
        <mesh
          filename="package://RM65B_EG24C2_description/DAE/Link_10.dae" />
      </geometry>
      <material
        name="">
        <color
          rgba="0.75294 0.75294 0.75294 1" />
      </material>
    </visual>
    <collision>
      <origin
        xyz="0 0 0"
        rpy="0 0 0" />
      <geometry>
        <mesh
          filename="package://RM65B_EG24C2_description/DAE/Link_10.dae" />
      </geometry>
    </collision>
  </link>
  <joint
    name="joint_10"
    type="revolute">
    <origin
      xyz="-0.009 -0.04 0.083"
      rpy="0 0 0" />
    <parent
      link="gripper_base_link" />
    <child
      link="Link_10" />
    <axis
      xyz="-1 0 0" />
    <limit
      lower="-0.82"
      upper="0"
      effort="1"
      velocity="1" />
    <mimic joint="gripper_joint" multiplier="-1"  offset="0"/>
  </joint>
  <link
    name="Link_12">
    <inertial>
      <origin
        xyz="0.006 0.011864 0.011367"
        rpy="0 0 0" />
      <mass
        value="0.0045068" />
      <inertia
        ixx="5.3203E-07"
        ixy="9.5605E-14"
        ixz="5.8578E-14"
        iyy="5.1288E-07"
        iyz="-9.4703E-08"
        izz="2.009E-07" />
    </inertial>
    <visual>
      <origin
        xyz="0 0 0"
        rpy="0 0 0" />
      <geometry>
        <mesh
          filename="package://RM65B_EG24C2_description/DAE/Link_12.dae" />
      </geometry>
      <material
        name="">
        <color
          rgba="0.75294 0.75294 0.75294 1" />
      </material>
    </visual>
    <collision>
      <origin
        xyz="0 0 0"
        rpy="0 0 0" />
      <geometry>
        <mesh
          filename="package://RM65B_EG24C2_description/DAE/Link_12.dae" />
      </geometry>
    </collision>
  </link>
  <joint
    name="joint_12"
    type="revolute">
    <origin
      xyz="0.003 0.0223 0.035591"
      rpy="0 0 0" />
    <parent
      link="Link_10" />
    <child
      link="Link_12" />
    <axis
      xyz="-1 0 0" />
    <limit
      lower="0"
      upper="0.82"
      effort="1"
      velocity="1" />
    <mimic joint="gripper_joint" multiplier="1"  offset="0"/>
  </joint>
  
  
  
</robot>
