<?xml version="1.0"?>
<robot name="rm65_B_left" xmlns:xacro="http://ros.org/wiki/xacro">
  <!-- Define constants -->
  <xacro:property name="mesh_path" value="package://dual_65B_arm_robot/meshes/" />
  <!-- Macro to define a generic link with mass, inertia, and visual -->
  <xacro:macro name="visual_collision" params="mesh">
    <visual>
      <origin xyz="0 0 0" rpy="0 0 0" />
      <geometry>
        <mesh filename="${mesh_path}${mesh}" />
      </geometry>
      <material name="">
        <color rgba="0.79216 0.81961 0.93333 1" />
      </material>
    </visual>
    <collision>
      <origin xyz="0 0 0" rpy="0 0 0" />
      <geometry>
        <mesh filename="${mesh_path}${mesh}" />
      </geometry>
    </collision>
  </xacro:macro>
  <link name="l_base_link">
    <inertial>
      <origin xyz="-0.00033271 -2.2498E-05 0.060153" rpy="0 0 0" />
      <mass value="0.83984" />
      <inertia ixx="0.0017115" ixy="4.0323E-06" ixz="-4.7032E-05"
        iyy="0.0016829" iyz="1.8665E-06" izz="0.00089155" />
    </inertial>
    <xacro:visual_collision mesh="l_base_link.STL" />
  </link>
  <link name="l_link1">
    <inertial>
      <origin xyz="-2.9675E-07 0.021107 -0.025188" rpy="0 0 0" />
      <mass value="0.59353" />
      <inertia ixx="0.0012661" ixy="-5.363E-09" ixz="-2.109E-09"
        iyy="0.0011816" iyz="-0.00021118" izz="0.00056131" />
    </inertial>
    <xacro:visual_collision mesh="l_link1.STL" />
  </link>
  <link
    name="l_link2">
    <inertial>
      <origin xyz="0.15226 2.3916E-07 -0.0062027" rpy="0 0 0" />
      <mass value="0.86416" />
      <inertia ixx="0.00063253" ixy="2.0103E-09" ixz="0.00042162"
        iyy="0.0020527" iyz="3.5857E-09" izz="0.0019528" />
    </inertial>
    <xacro:visual_collision mesh="l_link2.STL" />
  </link>
  <link name="l_link3">
    <inertial>
      <origin xyz="4.7194E-06 -0.059592 0.010268" rpy="0 0 0" />
      <mass value="0.28963" />
      <inertia ixx="0.00063737" ixy="-6.2601E-08" ixz="-3.5046E-08"
        iyy="0.00015649" iyz="-0.00014461" izz="0.00061418" />
    </inertial>
    <xacro:visual_collision mesh="l_link3.STL" />
  </link>
  <link name="l_link4">
    <inertial>
      <origin xyz="2.9186E-07 -0.018042 -0.02154" rpy="0 0 0" />
      <mass value="0.23942" />
      <inertia ixx="0.00028595" ixy="-2.3562E-09" ixz="1.3938E-09"
        iyy="0.00026273" iyz="4.424E-05" izz="0.0001199" />
    </inertial>
    <xacro:visual_collision mesh="l_link4.STL" />
  </link>
  <link name="l_link5">
    <inertial>
      <origin xyz="4.2301E-06 -0.059381 0.0070671" rpy="0 0 0" />
      <mass value="0.21879" />
      <inertia ixx="0.00035053" ixy="-2.8554E-08" ixz="-1.67E-08"
        iyy="0.00010492" iyz="-7.824E-05" izz="0.00033447" />
    </inertial>
    <xacro:visual_collision mesh="l_link5.STL" />
  </link>
  <link name="l_link6">
    <inertial>
      <origin xyz="-0.00081845 -1.3327E-05 0.016317" rpy="0 0 0" />
      <mass value="0.064802" />
      <inertia ixx="2.102E-05" ixy="-2.2708E-08" ixz="2.4381E-08"
        iyy="1.7985E-05" iyz="1.0173E-08" izz="3.1728E-05" />
    </inertial>
    <xacro:visual_collision mesh="l_link6.STL" />
  </link>

  <joint name="l_joint1" type="revolute">
    <origin xyz="0 0 0.2405" rpy="0 0 0" />
    <parent link="l_base_link" />
    <child link="l_link1" />
    <axis xyz="0 0 1" />
    <limit lower="-3.11" upper="3.11" effort="60" velocity="3.14" />
  </joint>
  <joint name="l_joint2" type="revolute">
    <origin xyz="0 0 0" rpy="1.5708 -1.5708 0" />
    <parent link="l_link1" />
    <child link="l_link2" />
    <axis xyz="0 0 1" />
    <limit lower="-2.27" upper="2.27" effort="60" velocity="3.14" />
  </joint>
  <joint name="l_joint3" type="revolute">
    <origin xyz="0.256 0 0" rpy="0 0 1.5708" />
    <parent link="l_link2" />
    <child link="l_link3" />
    <axis xyz="0 0 1" />
    <limit lower="-2.36" upper="2.36" effort="30" velocity="3.925" />
  </joint>
  <joint name="l_joint4" type="revolute">
    <origin xyz="0 -0.21 -0.00030007" rpy="1.5708 0 0" />
    <parent link="l_link3" />
    <child link="l_link4" />
    <axis xyz="0 0 1" />
    <limit lower="-3.11" upper="3.11" effort="10" velocity="3.925" />
  </joint>
  <joint name="l_joint5" type="revolute">
    <origin xyz="0 0 0" rpy="-1.5708 0 0" />
    <parent link="l_link4" />
    <child link="l_link5" />
    <axis xyz="0 0 1" />
    <limit lower="-2.23" upper="2.23" effort="10" velocity="3.925" />
  </joint>
  <joint name="l_joint6" type="revolute">
    <origin xyz="0 -0.115 -0.00029971" rpy="-1.5708 0 3.1416" />
    <parent link="l_link5" />
    <child link="l_link6" />
    <axis xyz="0 0 1" />
    <limit lower="-6.28" upper="6.28" effort="10" velocity="3.925" />
  </joint>
</robot>




